Workbook

Sheet Exploratory Data Analysis
B3: Fintech Application Explortory Data Analysis
B7: Gender Analysis | M7: previous app | O7: Favorite App
B9: Gender | C9: Count | D9: Percentage | O9: easypaisa | P9: sadapay | Q9: nayapay | R9: jazzcash
B10: {=_xlfn.UNIQUE(SINGLE_RESPONSES[Gender])} -> Male | C10: =COUNTIF(SINGLE_RESPONSES[Gender],B10) -> 106 | D10: =C10/150 -> 0.70666667 | N10: easypaisa | P10: =COUNTIFS(SINGLE_RESPONSES!$I2:$I151,'Exploratory Data Analysis'!$N10,SINGLE_RESPONSES!$G2:$G151,'Exploratory Data Analysis'!P$9) -> 7 | Q10: =COUNTIFS(SINGLE_RESPONSES!$I2:$I151,'Exploratory Data Analysis'!$N10,SINGLE_RESPONSES!$G2:$G151,'Exploratory Data Analysis'!Q$9) -> 7 | R10: =COUNTIFS(SINGLE_RESPONSES!$I2:$I151,'Exploratory Data Analysis'!$N10,SINGLE_RESPONSES!$G2:$G151,'Exploratory Data Analysis'!R$9) -> 26
B11: Female | C11: =COUNTIF(SINGLE_RESPONSES[Gender],B11) -> 43 | D11: =C11/150 -> 0.28666667 | N11: sadapay | O11: =COUNTIFS(SINGLE_RESPONSES!$I3:$I152,'Exploratory Data Analysis'!$N11,SINGLE_RESPONSES!$G3:$G152,'Exploratory Data Analysis'!O$9) -> 3 | Q11: =COUNTIFS(SINGLE_RESPONSES!$I3:$I152,'Exploratory Data Analysis'!$N11,SINGLE_RESPONSES!$G3:$G152,'Exploratory Data Analysis'!Q$9) -> 2 | R11: =COUNTIFS(SINGLE_RESPONSES!$I3:$I152,'Exploratory Data Analysis'!$N11,SINGLE_RESPONSES!$G3:$G152,'Exploratory Data Analysis'!R$9) -> 3
B12: Prefer not to say | C12: =COUNTIF(SINGLE_RESPONSES[Gender],B12) -> 1 | D12: =C12/150 -> 0.0066666667 | N12: nayapay | O12: =COUNTIFS(SINGLE_RESPONSES!$I4:$I153,'Exploratory Data Analysis'!$N12,SINGLE_RESPONSES!$G4:$G153,'Exploratory Data Analysis'!O$9) -> 4 | P12: =COUNTIFS(SINGLE_RESPONSES!$I4:$I153,'Exploratory Data Analysis'!$N12,SINGLE_RESPONSES!$G4:$G153,'Exploratory Data Analysis'!P$9) -> 0 | R12: =COUNTIFS(SINGLE_RESPONSES!$I4:$I153,'Exploratory Data Analysis'!$N12,SINGLE_RESPONSES!$G4:$G153,'Exploratory Data Analysis'!R$9) -> 5
N13: jazzcash | O13: =COUNTIFS(SINGLE_RESPONSES!$I5:$I154,'Exploratory Data Analysis'!$N13,SINGLE_RESPONSES!$G5:$G154,'Exploratory Data Analysis'!O$9) -> 20 | P13: =COUNTIFS(SINGLE_RESPONSES!$I5:$I154,'Exploratory Data Analysis'!$N13,SINGLE_RESPONSES!$G5:$G154,'Exploratory Data Analysis'!P$9) -> 9 | Q13: =COUNTIFS(SINGLE_RESPONSES!$I5:$I154,'Exploratory Data Analysis'!$N13,SINGLE_RESPONSES!$G5:$G154,'Exploratory Data Analysis'!Q$9) -> 9
B24: Age Group Analysis | M24: Reasons why people are moving to other apps | N24: Favorite App
N25: easypaisa | O25: jazzcash | P25: sadapay | Q25: nayapay
M26: PULL factors
B27: Index | C27: Age Group | D27: Percentage | E27: Count | M27: Better UX | N27: =COUNTIFS('Reason_to_switch_&_keep_using'!$G:$G,$M27,'Reason_to_switch_&_keep_using'!$D:$D,N$25) -> 4 | O27: =COUNTIFS('Reason_to_switch_&_keep_using'!$G:$G,$M27,'Reason_to_switch_&_keep_using'!$D:$D,O$25) -> 10 | P27: =COUNTIFS('Reason_to_switch_&_keep_using'!$G:$G,$M27,'Reason_to_switch_&_keep_using'!$D:$D,P$25) -> 4 | Q27: =COUNTIFS('Reason_to_switch_&_keep_using'!$G:$G,$M27,'Reason_to_switch_&_keep_using'!$D:$D,Q$25) -> 0
B28: {=_xlfn._xlws.SORT(_xlfn.UNIQUE(SINGLE_RESPONSES[coding]))} -> 1 | C28: 18-29 | D28: =E28/150 -> 0.84666667 | E28: =COUNTIF(SINGLE_RESPONSES[coding],B28) -> 127 | M28: Better Features | N28: =COUNTIFS('Reason_to_switch_&_keep_using'!$G:$G,$M28,'Reason_to_switch_&_keep_using'!$D:$D,N$25) -> 4 | O28: =COUNTIFS('Reason_to_switch_&_keep_using'!$G:$G,$M28,'Reason_to_switch_&_keep_using'!$D:$D,O$25) -> 3 | P28: =COUNTIFS('Reason_to_switch_&_keep_using'!$G:$G,$M28,'Reason_to_switch_&_keep_using'!$D:$D,P$25) -> 1 | Q28: =COUNTIFS('Reason_to_switch_&_keep_using'!$G:$G,$M28,'Reason_to_switch_&_keep_using'!$D:$D,Q$25) -> 2
B29: 2 | C29: 30-41 | D29: =E29/150 -> 0.1 | E29: =COUNTIF(SINGLE_RESPONSES[coding],B29) -> 15 | M29: Performance | N29: =COUNTIFS('Reason_to_switch_&_keep_using'!$G:$G,$M29,'Reason_to_switch_&_keep_using'!$D:$D,N$25) -> 1 | O29: =COUNTIFS('Reason_to_switch_&_keep_using'!$G:$G,$M29,'Reason_to_switch_&_keep_using'!$D:$D,O$25) -> 4 | P29: =COUNTIFS('Reason_to_switch_&_keep_using'!$G:$G,$M29,'Reason_to_switch_&_keep_using'!$D:$D,P$25) -> 0 | Q29: =COUNTIFS('Reason_to_switch_&_keep_using'!$G:$G,$M29,'Reason_to_switch_&_keep_using'!$D:$D,Q$25) -> 0
B30: 3 | C30: 42-54 | D30: =E30/150 -> 0.033333333 | E30: =COUNTIF(SINGLE_RESPONSES[coding],B30) -> 5 | M30: Good Customer Services | N30: =COUNTIFS('Reason_to_switch_&_keep_using'!$G:$G,$M30,'Reason_to_switch_&_keep_using'!$D:$D,N$25) -> 1 | O30: =COUNTIFS('Reason_to_switch_&_keep_using'!$G:$G,$M30,'Reason_to_switch_&_keep_using'!$D:$D,O$25) -> 1 | P30: =COUNTIFS('Reason_to_switch_&_keep_using'!$G:$G,$M30,'Reason_to_switch_&_keep_using'!$D:$D,P$25) -> 1 | Q30: =COUNTIFS('Reason_to_switch_&_keep_using'!$G:$G,$M30,'Reason_to_switch_&_keep_using'!$D:$D,Q$25) -> 0
B31: 4 | C31: 55-64 | D31: =E31/150 -> 0.013333333 | E31: =COUNTIF(SINGLE_RESPONSES[coding],B31) -> 2 | M31: Ecosystem Advantage | N31: =COUNTIFS('Reason_to_switch_&_keep_using'!$G:$G,$M31,'Reason_to_switch_&_keep_using'!$D:$D,N$25) -> 2 | O31: =COUNTIFS('Reason_to_switch_&_keep_using'!$G:$G,$M31,'Reason_to_switch_&_keep_using'!$D:$D,O$25) -> 3 | P31: =COUNTIFS('Reason_to_switch_&_keep_using'!$G:$G,$M31,'Reason_to_switch_&_keep_using'!$D:$D,P$25) -> 0 | Q31: =COUNTIFS('Reason_to_switch_&_keep_using'!$G:$G,$M31,'Reason_to_switch_&_keep_using'!$D:$D,Q$25) -> 0
B32: 5 | C32: 66 and above | D32: =E32/150 -> 0.0066666667 | E32: =COUNTIF(SINGLE_RESPONSES[coding],B32) -> 1 | M32: Greater Trust | N32: =COUNTIFS('Reason_to_switch_&_keep_using'!$G:$G,$M32,'Reason_to_switch_&_keep_using'!$D:$D,N$25) -> 0 | O32: =COUNTIFS('Reason_to_switch_&_keep_using'!$G:$G,$M32,'Reason_to_switch_&_keep_using'!$D:$D,O$25) -> 0 | P32: =COUNTIFS('Reason_to_switch_&_keep_using'!$G:$G,$M32,'Reason_to_switch_&_keep_using'!$D:$D,P$25) -> 0 | Q32: =COUNTIFS('Reason_to_switch_&_keep_using'!$G:$G,$M32,'Reason_to_switch_&_keep_using'!$D:$D,Q$25) -> 1
M33: Explore | N33: =COUNTIFS('Reason_to_switch_&_keep_using'!$G:$G,$M33,'Reason_to_switch_&_keep_using'!$D:$D,N$25) -> 6 | O33: =COUNTIFS('Reason_to_switch_&_keep_using'!$G:$G,$M33,'Reason_to_switch_&_keep_using'!$D:$D,O$25) -> 7 | P33: =COUNTIFS('Reason_to_switch_&_keep_using'!$G:$G,$M33,'Reason_to_switch_&_keep_using'!$D:$D,P$25) -> 3 | Q33: =COUNTIFS('Reason_to_switch_&_keep_using'!$G:$G,$M33,'Reason_to_switch_&_keep_using'!$D:$D,Q$25) -> 3
M34: PUSH Factors
M35: Trust issues | N35: =COUNTIFS('Reason_to_switch_&_keep_using'!$G:$G,$M35,'Reason_to_switch_&_keep_using'!$D:$D,N$25) -> 1 | O35: =COUNTIFS('Reason_to_switch_&_keep_using'!$G:$G,$M35,'Reason_to_switch_&_keep_using'!$D:$D,O$25) -> 2 | P35: =COUNTIFS('Reason_to_switch_&_keep_using'!$G:$G,$M35,'Reason_to_switch_&_keep_using'!$D:$D,P$25) -> 1 | Q35: =COUNTIFS('Reason_to_switch_&_keep_using'!$G:$G,$M35,'Reason_to_switch_&_keep_using'!$D:$D,Q$25) -> 1
M36: Technical Failures | N36: =COUNTIFS('Reason_to_switch_&_keep_using'!$G:$G,$M36,'Reason_to_switch_&_keep_using'!$D:$D,N$25) -> 3 | O36: =COUNTIFS('Reason_to_switch_&_keep_using'!$G:$G,$M36,'Reason_to_switch_&_keep_using'!$D:$D,O$25) -> 0 | P36: =COUNTIFS('Reason_to_switch_&_keep_using'!$G:$G,$M36,'Reason_to_switch_&_keep_using'!$D:$D,P$25) -> 3 | Q36: =COUNTIFS('Reason_to_switch_&_keep_using'!$G:$G,$M36,'Reason_to_switch_&_keep_using'!$D:$D,Q$25) -> 2
M37: Account Access Issues | N37: =COUNTIFS('Reason_to_switch_&_keep_using'!$G:$G,$M37,'Reason_to_switch_&_keep_using'!$D:$D,N$25) -> 0 | O37: =COUNTIFS('Reason_to_switch_&_keep_using'!$G:$G,$M37,'Reason_to_switch_&_keep_using'!$D:$D,O$25) -> 2 | P37: =COUNTIFS('Reason_to_switch_&_keep_using'!$G:$G,$M37,'Reason_to_switch_&_keep_using'!$D:$D,P$25) -> 0 | Q37: =COUNTIFS('Reason_to_switch_&_keep_using'!$G:$G,$M37,'Reason_to_switch_&_keep_using'!$D:$D,Q$25) -> 0
M38: Bad UX | N38: =COUNTIFS('Reason_to_switch_&_keep_using'!$G:$G,$M38,'Reason_to_switch_&_keep_using'!$D:$D,N$25) -> 0 | O38: =COUNTIFS('Reason_to_switch_&_keep_using'!$G:$G,$M38,'Reason_to_switch_&_keep_using'!$D:$D,O$25) -> 2 | P38: =COUNTIFS('Reason_to_switch_&_keep_using'!$G:$G,$M38,'Reason_to_switch_&_keep_using'!$D:$D,P$25) -> 0 | Q38: =COUNTIFS('Reason_to_switch_&_keep_using'!$G:$G,$M38,'Reason_to_switch_&_keep_using'!$D:$D,Q$25) -> 0
M39: Poor Customer Service | N39: =COUNTIFS('Reason_to_switch_&_keep_using'!$G:$G,$M39,'Reason_to_switch_&_keep_using'!$D:$D,N$25) -> 0 | O39: =COUNTIFS('Reason_to_switch_&_keep_using'!$G:$G,$M39,'Reason_to_switch_&_keep_using'!$D:$D,O$25) -> 0 | P39: =COUNTIFS('Reason_to_switch_&_keep_using'!$G:$G,$M39,'Reason_to_switch_&_keep_using'!$D:$D,P$25) -> 0 | Q39: =COUNTIFS('Reason_to_switch_&_keep_using'!$G:$G,$M39,'Reason_to_switch_&_keep_using'!$D:$D,Q$25) -> 0
B41: Awareness
B42: App | C42: Count | D42: Percentage
B43: easypaisa | C43: =COUNTIF(Table10_1[Application(Awareness)],'Exploratory Data Analysis'!B43) -> 100 | D43: =C43/150 -> 0.66666667
B44: sadapay | C44: =COUNTIF(Table10_1[Application(Awareness)],'Exploratory Data Analysis'!B44) -> 61 | D44: =C44/150 -> 0.40666667
B45: jazzcash | C45: =COUNTIF(Table10_1[Application(Awareness)],'Exploratory Data Analysis'!B45) -> 114 | D45: =C45/150 -> 0.76 | M45: Reasons why people want to keep using their current app | N45: Favorite App
B46: nayapay | C46: =COUNTIF(Table10_1[Application(Awareness)],'Exploratory Data Analysis'!B46) -> 55 | D46: =C46/150 -> 0.36666667 | N46: easypaisa | O46: jazzcash | P46: sadapay | Q46: nayapay
M47: Better UX | N47: =COUNTIFS('Reason_to_switch_&_keep_using'!$K:$K,'Exploratory Data Analysis'!$M47,'Reason_to_switch_&_keep_using'!$D:$D,'Exploratory Data Analysis'!N$46) -> 15 | O47: =COUNTIFS('Reason_to_switch_&_keep_using'!$K:$K,'Exploratory Data Analysis'!$M47,'Reason_to_switch_&_keep_using'!$D:$D,'Exploratory Data Analysis'!O$46) -> 26 | P47: =COUNTIFS('Reason_to_switch_&_keep_using'!$K:$K,'Exploratory Data Analysis'!$M47,'Reason_to_switch_&_keep_using'!$D:$D,'Exploratory Data Analysis'!P$46) -> 8 | Q47: =COUNTIFS('Reason_to_switch_&_keep_using'!$K:$K,'Exploratory Data Analysis'!$M47,'Reason_to_switch_&_keep_using'!$D:$D,'Exploratory Data Analysis'!Q$46) -> 8
M48: Ecosystem Advantage | N48: =COUNTIFS('Reason_to_switch_&_keep_using'!$K:$K,'Exploratory Data Analysis'!$M48,'Reason_to_switch_&_keep_using'!$D:$D,'Exploratory Data Analysis'!N$46) -> 3 | O48: =COUNTIFS('Reason_to_switch_&_keep_using'!$K:$K,'Exploratory Data Analysis'!$M48,'Reason_to_switch_&_keep_using'!$D:$D,'Exploratory Data Analysis'!O$46) -> 7 | P48: =COUNTIFS('Reason_to_switch_&_keep_using'!$K:$K,'Exploratory Data Analysis'!$M48,'Reason_to_switch_&_keep_using'!$D:$D,'Exploratory Data Analysis'!P$46) -> 0 | Q48: =COUNTIFS('Reason_to_switch_&_keep_using'!$K:$K,'Exploratory Data Analysis'!$M48,'Reason_to_switch_&_keep_using'!$D:$D,'Exploratory Data Analysis'!Q$46) -> 0
M49: Performance | N49: =COUNTIFS('Reason_to_switch_&_keep_using'!$K:$K,'Exploratory Data Analysis'!$M49,'Reason_to_switch_&_keep_using'!$D:$D,'Exploratory Data Analysis'!N$46) -> 6 | O49: =COUNTIFS('Reason_to_switch_&_keep_using'!$K:$K,'Exploratory Data Analysis'!$M49,'Reason_to_switch_&_keep_using'!$D:$D,'Exploratory Data Analysis'!O$46) -> 9 | P49: =COUNTIFS('Reason_to_switch_&_keep_using'!$K:$K,'Exploratory Data Analysis'!$M49,'Reason_to_switch_&_keep_using'!$D:$D,'Exploratory Data Analysis'!P$46) -> 1 | Q49: =COUNTIFS('Reason_to_switch_&_keep_using'!$K:$K,'Exploratory Data Analysis'!$M49,'Reason_to_switch_&_keep_using'!$D:$D,'Exploratory Data Analysis'!Q$46) -> 2
M50: Better features | N50: =COUNTIFS('Reason_to_switch_&_keep_using'!$K:$K,'Exploratory Data Analysis'!$M50,'Reason_to_switch_&_keep_using'!$D:$D,'Exploratory Data Analysis'!N$46) -> 7 | O50: =COUNTIFS('Reason_to_switch_&_keep_using'!$K:$K,'Exploratory Data Analysis'!$M50,'Reason_to_switch_&_keep_using'!$D:$D,'Exploratory Data Analysis'!O$46) -> 8 | P50: =COUNTIFS('Reason_to_switch_&_keep_using'!$K:$K,'Exploratory Data Analysis'!$M50,'Reason_to_switch_&_keep_using'!$D:$D,'Exploratory Data Analysis'!P$46) -> 5 | Q50: =COUNTIFS('Reason_to_switch_&_keep_using'!$K:$K,'Exploratory Data Analysis'!$M50,'Reason_to_switch_&_keep_using'!$D:$D,'Exploratory Data Analysis'!Q$46) -> 7
M51: Other | N51: =COUNTIFS('Reason_to_switch_&_keep_using'!$K:$K,'Exploratory Data Analysis'!$M51,'Reason_to_switch_&_keep_using'!$D:$D,'Exploratory Data Analysis'!N$46) -> 2 | O51: =COUNTIFS('Reason_to_switch_&_keep_using'!$K:$K,'Exploratory Data Analysis'!$M51,'Reason_to_switch_&_keep_using'!$D:$D,'Exploratory Data Analysis'!O$46) -> 6 | P51: =COUNTIFS('Reason_to_switch_&_keep_using'!$K:$K,'Exploratory Data Analysis'!$M51,'Reason_to_switch_&_keep_using'!$D:$D,'Exploratory Data Analysis'!P$46) -> 0 | Q51: =COUNTIFS('Reason_to_switch_&_keep_using'!$K:$K,'Exploratory Data Analysis'!$M51,'Reason_to_switch_&_keep_using'!$D:$D,'Exploratory Data Analysis'!Q$46) -> 1
M52: Greater Trust | N52: =COUNTIFS('Reason_to_switch_&_keep_using'!$K:$K,'Exploratory Data Analysis'!$M52,'Reason_to_switch_&_keep_using'!$D:$D,'Exploratory Data Analysis'!N$46) -> 5 | O52: =COUNTIFS('Reason_to_switch_&_keep_using'!$K:$K,'Exploratory Data Analysis'!$M52,'Reason_to_switch_&_keep_using'!$D:$D,'Exploratory Data Analysis'!O$46) -> 1 | P52: =COUNTIFS('Reason_to_switch_&_keep_using'!$K:$K,'Exploratory Data Analysis'!$M52,'Reason_to_switch_&_keep_using'!$D:$D,'Exploratory Data Analysis'!P$46) -> 0 | Q52: =COUNTIFS('Reason_to_switch_&_keep_using'!$K:$K,'Exploratory Data Analysis'!$M52,'Reason_to_switch_&_keep_using'!$D:$D,'Exploratory Data Analysis'!Q$46) -> 2
M53: Good Customer Service | N53: =COUNTIFS('Reason_to_switch_&_keep_using'!$K:$K,'Exploratory Data Analysis'!$M53,'Reason_to_switch_&_keep_using'!$D:$D,'Exploratory Data Analysis'!N$46) -> 3 | O53: =COUNTIFS('Reason_to_switch_&_keep_using'!$K:$K,'Exploratory Data Analysis'!$M53,'Reason_to_switch_&_keep_using'!$D:$D,'Exploratory Data Analysis'!O$46) -> 6 | P53: =COUNTIFS('Reason_to_switch_&_keep_using'!$K:$K,'Exploratory Data Analysis'!$M53,'Reason_to_switch_&_keep_using'!$D:$D,'Exploratory Data Analysis'!P$46) -> 1 | Q53: =COUNTIFS('Reason_to_switch_&_keep_using'!$K:$K,'Exploratory Data Analysis'!$M53,'Reason_to_switch_&_keep_using'!$D:$D,'Exploratory Data Analysis'!Q$46) -> 1
M54: Financial benefits | N54: =COUNTIFS('Reason_to_switch_&_keep_using'!$K:$K,'Exploratory Data Analysis'!$M54,'Reason_to_switch_&_keep_using'!$D:$D,'Exploratory Data Analysis'!N$46) -> 0 | O54: =COUNTIFS('Reason_to_switch_&_keep_using'!$K:$K,'Exploratory Data Analysis'!$M54,'Reason_to_switch_&_keep_using'!$D:$D,'Exploratory Data Analysis'!O$46) -> 0 | P54: =COUNTIFS('Reason_to_switch_&_keep_using'!$K:$K,'Exploratory Data Analysis'!$M54,'Reason_to_switch_&_keep_using'!$D:$D,'Exploratory Data Analysis'!P$46) -> 0 | Q54: =COUNTIFS('Reason_to_switch_&_keep_using'!$K:$K,'Exploratory Data Analysis'!$M54,'Reason_to_switch_&_keep_using'!$D:$D,'Exploratory Data Analysis'!Q$46) -> 2
B56: Favorite App
B57: App | C57: Count | D57: Percentage
B58: {=_xlfn.UNIQUE(SINGLE_RESPONSES[FAVORITE])} -> easypaisa | C58: =COUNTIF(SINGLE_RESPONSES[FAVORITE],B58) -> 43 | D58: =C58/150 -> 0.28666667
...

Sheet Top_of_Mind_Awareness
B1: =COUNTA(SINGLE_RESPONSES[TOM]) -> 150
B6: TOMA | C6: Count | D6: % | G6: TOTAL AWARENESS | H6: Count | I6: % | L6: CURRENT USAGE | M6: Count | N6: % | Q6: EVER USED | R6: Count | S6: % | V6: FAVORITE | W6: Count | X6: %
B7: {=_xlfn.UNIQUE(SINGLE_RESPONSES[TOM])} -> easypaisa | C7: =COUNTIF(SINGLE_RESPONSES[TOM],B7) -> 46 | D7: =C7/$B$1 -> 0.30666667 | G7: {=_xlfn.UNIQUE(SINGLE_RESPONSES[TOM])} -> easypaisa | H7: 100 | I7: =H7/$B$1 -> 0.66666667 | L7: {=_xlfn.UNIQUE(SINGLE_RESPONSES[TOM])} -> easypaisa | M7: =COUNTIF(CURRENT_USAGE[APP],L7) -> 77 | N7: =M7/$B$1 -> 0.51333333 | Q7: {=_xlfn.UNIQUE(SINGLE_RESPONSES[TOM])} -> easypaisa | R7: =COUNTIF(EVER_USED[APP],Q7) -> 89 | S7: =R7/$B$1 -> 0.59333333 | V7: {=_xlfn.UNIQUE(SINGLE_RESPONSES[TOM])} -> easypaisa | W7: =COUNTIF(SINGLE_RESPONSES[FAVORITE],V7) -> 43 | X7: =W7/$B$1 -> 0.28666667
B8: sadapay | C8: =COUNTIF(SINGLE_RESPONSES[TOM],B8) -> 8 | D8: =C8/$B$1 -> 0.053333333 | G8: sadapay | H8: 61 | I8: =H8/150 -> 0.40666667 | L8: sadapay | M8: =COUNTIF(CURRENT_USAGE[APP],L8) -> 41 | N8: =M8/$B$1 -> 0.27333333 | Q8: sadapay | R8: =COUNTIF(EVER_USED[APP],Q8) -> 57 | S8: =R8/$B$1 -> 0.38 | V8: sadapay | W8: =COUNTIF(SINGLE_RESPONSES[FAVORITE],V8) -> 18 | X8: =W8/$B$1 -> 0.12
B9: jazzcash | C9: =COUNTIF(SINGLE_RESPONSES[TOM],B9) -> 83 | D9: =C9/$B$1 -> 0.55333333 | G9: jazzcash | H9: 114 | I9: =Engineered_Awareness_data!G154 -> 0.76 | L9: jazzcash | M9: =COUNTIF(CURRENT_USAGE[APP],L9) -> 93 | N9: =M9/$B$1 -> 0.62 | Q9: jazzcash | R9: =COUNTIF(EVER_USED[APP],Q9) -> 99 | S9: =R9/$B$1 -> 0.66 | V9: jazzcash | W9: =COUNTIF(SINGLE_RESPONSES[FAVORITE],V9) -> 65 | X9: =W9/$B$1 -> 0.43333333
B10: nayapay | C10: =COUNTIF(SINGLE_RESPONSES[TOM],B10) -> 10 | D10: =C10/$B$1 -> 0.066666667 | G10: nayapay | H10: 55 | I10: =H10/$B$1 -> 0.36666667 | L10: nayapay | M10: =COUNTIF(CURRENT_USAGE[APP],L10) -> 43 | N10: =M10/$B$1 -> 0.28666667 | Q10: nayapay | R10: =COUNTIF(EVER_USED[APP],Q10) -> 53 | S10: =R10/$B$1 -> 0.35333333 | V10: nayapay | W10: =COUNTIF(SINGLE_RESPONSES[FAVORITE],V10) -> 24 | X10: =W10/$B$1 -> 0.16
B11: bankaccount | C11: =COUNTIF(SINGLE_RESPONSES[TOM],B11) -> 1 | D11: =C11/$B$1 -> 0.0066666667 | G11: bankaccount | H11: =COUNTIF(Engineered_Awareness_data!$B$2:$B$151,Top_of_Mind_Awareness!G11) -> 0 | I11: =H11/$B$1 -> 0 | L11: bankaccount | M11: =COUNTIF(CURRENT_USAGE[APP],L11) -> 0 | N11: =M11/$B$1 -> 0 | Q11: bankaccount | R11: =COUNTIF(EVER_USED[APP],Q11) -> 0 | S11: =R11/$B$1 -> 0 | V11: bankaccount | W11: =COUNTIF(SINGLE_RESPONSES[FAVORITE],V11) -> 0 | X11: =W11/$B$1 -> 0
B12: mashreq | C12: =COUNTIF(SINGLE_RESPONSES[TOM],B12) -> 1 | D12: =C12/$B$1 -> 0.0066666667 | G12: mashreq | H12: =COUNTIF(Engineered_Awareness_data!$B$2:$B$151,Top_of_Mind_Awareness!G12) -> 0 | I12: =H12/$B$1 -> 0 | L12: mashreq | M12: =COUNTIF(CURRENT_USAGE[APP],L12) -> 0 | N12: =M12/$B$1 -> 0 | Q12: mashreq | R12: =COUNTIF(EVER_USED[APP],Q12) -> 0 | S12: =R12/$B$1 -> 0 | V12: mashreq | W12: =COUNTIF(SINGLE_RESPONSES[FAVORITE],V12) -> 0 | X12: =W12/$B$1 -> 0
B13: hbl | C13: =COUNTIF(SINGLE_RESPONSES[TOM],B13) -> 1 | D13: =C13/$B$1 -> 0.0066666667 | G13: hbl | H13: =COUNTIF(Engineered_Awareness_data!$B$2:$B$151,Top_of_Mind_Awareness!G13) -> 0 | I13: =H13/$B$1 -> 0 | L13: hbl | M13: =COUNTIF(CURRENT_USAGE[APP],L13) -> 0 | N13: =M13/$B$1 -> 0 | Q13: hbl | R13: =COUNTIF(EVER_USED[APP],Q13) -> 0 | S13: =R13/$B$1 -> 0 | V13: hbl | W13: =COUNTIF(SINGLE_RESPONSES[FAVORITE],V13) -> 0 | X13: =W13/$B$1 -> 0
C14: =SUM(C7:C13) -> 150 | D14: =C14/$B$1 -> 1 | I14: =SUM(I7:I13) -> 2.2
C19: jazzcash | D19: easypaisa | E19: sadapay | F19: nayapay
B20: AWARENESS | C20: =Engineered_Awareness_data!G154 -> 0.76 | D20: =Engineered_Awareness_data!H154 -> 0.66666667 | E20: =Engineered_Awareness_data!I154 -> 0.40666667 | F20: =Engineered_Awareness_data!J154 -> 0.36666667
B21: EVER USED | C21: =S9 -> 0.66 | D21: =S7 -> 0.59333333 | E21: =S8 -> 0.38 | F21: =S10 -> 0.35333333
B22: CURRENT USAGE | C22: =N9 -> 0.62 | D22: =N7 -> 0.51333333 | E22: =N8 -> 0.27333333 | F22: =S10 -> 0.35333333
B23: FAVORITE | C23: =X9 -> 0.43333333 | D23: =X7 -> 0.28666667 | E23: =X8 -> 0.12 | F23: =X10 -> 0.16
C24: =C23/C20 -> 0.57017544 | D24: =D23/D20 -> 0.43 | E24: =E23/E20 -> 0.29508197 | F24: =F23/F20 -> 0.43636364

Sheet Imagery_Analysis
D6: IMAGERY | E6: {=TRANSPOSE(_xlfn.UNIQUE(IMAGERY[APP]))} -> sadapay | F6: easypaisa | G6: jazzcash | H6: nayapay
D7: {=_xlfn.UNIQUE(IMAGERY[IMAGERY])} -> Best app interface and user experience (UX) | E7: =COUNTIFS(IMAGERY_Data!$B$2:$B$1190,Imagery_Analysis!$D7,IMAGERY_Data!$C$2:$C$1190,Imagery_Analysis!E$6) -> 16 | F7: =COUNTIFS(IMAGERY_Data!$B$2:$B$1190,Imagery_Analysis!$D7,IMAGERY_Data!$C$2:$C$1190,Imagery_Analysis!F$6) -> 44 | G7: =COUNTIFS(IMAGERY_Data!$B$2:$B$1190,Imagery_Analysis!$D7,IMAGERY_Data!$C$2:$C$1190,Imagery_Analysis!G$6) -> 66 | H7: =COUNTIFS(IMAGERY_Data!$B$2:$B$1190,Imagery_Analysis!$D7,IMAGERY_Data!$C$2:$C$1190,Imagery_Analysis!H$6) -> 24
D8: Most reliable (least likely to have server/network down issues) | E8: =COUNTIFS(IMAGERY_Data!$B$2:$B$1190,Imagery_Analysis!$D8,IMAGERY_Data!$C$2:$C$1190,Imagery_Analysis!E$6) -> 20 | F8: =COUNTIFS(IMAGERY_Data!$B$2:$B$1190,Imagery_Analysis!$D8,IMAGERY_Data!$C$2:$C$1190,Imagery_Analysis!F$6) -> 48 | G8: =COUNTIFS(IMAGERY_Data!$B$2:$B$1190,Imagery_Analysis!$D8,IMAGERY_Data!$C$2:$C$1190,Imagery_Analysis!G$6) -> 62 | H8: =COUNTIFS(IMAGERY_Data!$B$2:$B$1190,Imagery_Analysis!$D8,IMAGERY_Data!$C$2:$C$1190,Imagery_Analysis!H$6) -> 19
D9: Offers the best discounts, deals, and cashbacks | E9: =COUNTIFS(IMAGERY_Data!$B$2:$B$1190,Imagery_Analysis!$D9,IMAGERY_Data!$C$2:$C$1190,Imagery_Analysis!E$6) -> 4 | F9: =COUNTIFS(IMAGERY_Data!$B$2:$B$1190,Imagery_Analysis!$D9,IMAGERY_Data!$C$2:$C$1190,Imagery_Analysis!F$6) -> 53 | G9: =COUNTIFS(IMAGERY_Data!$B$2:$B$1190,Imagery_Analysis!$D9,IMAGERY_Data!$C$2:$C$1190,Imagery_Analysis!G$6) -> 83 | H9: =COUNTIFS(IMAGERY_Data!$B$2:$B$1190,Imagery_Analysis!$D9,IMAGERY_Data!$C$2:$C$1190,Imagery_Analysis!H$6) -> 9
D10: Good customer service and quick issue resolution | E10: =COUNTIFS(IMAGERY_Data!$B$2:$B$1190,Imagery_Analysis!$D10,IMAGERY_Data!$C$2:$C$1190,Imagery_Analysis!E$6) -> 17 | F10: =COUNTIFS(IMAGERY_Data!$B$2:$B$1190,Imagery_Analysis!$D10,IMAGERY_Data!$C$2:$C$1190,Imagery_Analysis!F$6) -> 50 | G10: =COUNTIFS(IMAGERY_Data!$B$2:$B$1190,Imagery_Analysis!$D10,IMAGERY_Data!$C$2:$C$1190,Imagery_Analysis!G$6) -> 60 | H10: =COUNTIFS(IMAGERY_Data!$B$2:$B$1190,Imagery_Analysis!$D10,IMAGERY_Data!$C$2:$C$1190,Imagery_Analysis!H$6) -> 22
D11: Lowest transaction fees and free inter-bank fund transfers (IBFT) | E11: =COUNTIFS(IMAGERY_Data!$B$2:$B$1190,Imagery_Analysis!$D11,IMAGERY_Data!$C$2:$C$1190,Imagery_Analysis!E$6) -> 20 | F11: =COUNTIFS(IMAGERY_Data!$B$2:$B$1190,Imagery_Analysis!$D11,IMAGERY_Data!$C$2:$C$1190,Imagery_Analysis!F$6) -> 51 | G11: =COUNTIFS(IMAGERY_Data!$B$2:$B$1190,Imagery_Analysis!$D11,IMAGERY_Data!$C$2:$C$1190,Imagery_Analysis!G$6) -> 51 | H11: =COUNTIFS(IMAGERY_Data!$B$2:$B$1190,Imagery_Analysis!$D11,IMAGERY_Data!$C$2:$C$1190,Imagery_Analysis!H$6) -> 27
D12: Strongest security features | E12: =COUNTIFS(IMAGERY_Data!$B$2:$B$1190,Imagery_Analysis!$D12,IMAGERY_Data!$C$2:$C$1190,Imagery_Analysis!E$6) -> 14 | F12: =COUNTIFS(IMAGERY_Data!$B$2:$B$1190,Imagery_Analysis!$D12,IMAGERY_Data!$C$2:$C$1190,Imagery_Analysis!F$6) -> 44 | G12: =COUNTIFS(IMAGERY_Data!$B$2:$B$1190,Imagery_Analysis!$D12,IMAGERY_Data!$C$2:$C$1190,Imagery_Analysis!G$6) -> 69 | H12: =COUNTIFS(IMAGERY_Data!$B$2:$B$1190,Imagery_Analysis!$D12,IMAGERY_Data!$C$2:$C$1190,Imagery_Analysis!H$6) -> 22
D13: Easiest and fastest process for opening an account or ordering a physical debit card | E13: =COUNTIFS(IMAGERY_Data!$B$2:$B$1190,Imagery_Analysis!$D13,IMAGERY_Data!$C$2:$C$1190,Imagery_Analysis!E$6) -> 20 | F13: =COUNTIFS(IMAGERY_Data!$B$2:$B$1190,Imagery_Analysis!$D13,IMAGERY_Data!$C$2:$C$1190,Imagery_Analysis!F$6) -> 44 | G13: =COUNTIFS(IMAGERY_Data!$B$2:$B$1190,Imagery_Analysis!$D13,IMAGERY_Data!$C$2:$C$1190,Imagery_Analysis!G$6) -> 59 | H13: =COUNTIFS(IMAGERY_Data!$B$2:$B$1190,Imagery_Analysis!$D13,IMAGERY_Data!$C$2:$C$1190,Imagery_Analysis!H$6) -> 26
D14: Best app for international payments | E14: =COUNTIFS(IMAGERY_Data!$B$2:$B$1190,Imagery_Analysis!$D14,IMAGERY_Data!$C$2:$C$1190,Imagery_Analysis!E$6) -> 33 | F14: =COUNTIFS(IMAGERY_Data!$B$2:$B$1190,Imagery_Analysis!$D14,IMAGERY_Data!$C$2:$C$1190,Imagery_Analysis!F$6) -> 27 | G14: =COUNTIFS(IMAGERY_Data!$B$2:$B$1190,Imagery_Analysis!$D14,IMAGERY_Data!$C$2:$C$1190,Imagery_Analysis!G$6) -> 48 | H14: =COUNTIFS(IMAGERY_Data!$B$2:$B$1190,Imagery_Analysis!$D14,IMAGERY_Data!$C$2:$C$1190,Imagery_Analysis!H$6) -> 37
D18: IMAGERY | E18: {=TRANSPOSE(_xlfn.UNIQUE(IMAGERY[APP]))} -> sadapay | F18: easypaisa | G18: jazzcash | H18: nayapay
D19: {=_xlfn.UNIQUE(IMAGERY[IMAGERY])} -> Best app interface and user experience (UX) | E19: =E7/150 -> 0.10666667 | F19: =F7/150 -> 0.29333333 | G19: =G7/150 -> 0.44 | H19: =H7/150 -> 0.16
D20: Most reliable (least likely to have server/network down issues) | E20: =E8/150 -> 0.13333333 | F20: =F8/150 -> 0.32 | G20: =G8/150 -> 0.41333333 | H20: =H8/150 -> 0.12666667
D21: Offers the best discounts, deals, and cashbacks | E21: =E9/150 -> 0.026666667 | F21: =F9/150 -> 0.35333333 | G21: =G9/150 -> 0.55333333 | H21: =H9/150 -> 0.06
D22: Good customer service and quick issue resolution | E22: =E10/150 -> 0.11333333 | F22: =F10/150 -> 0.33333333 | G22: =G10/150 -> 0.4 | H22: =H10/150 -> 0.14666667
D23: Lowest transaction fees and free inter-bank fund transfers (IBFT) | E23: =E11/150 -> 0.13333333 | F23: =F11/150 -> 0.34 | G23: =G11/150 -> 0.34 | H23: =H11/150 -> 0.18
D24: Strongest security features | E24: =E12/150 -> 0.093333333 | F24: =F12/150 -> 0.29333333 | G24: =G12/150 -> 0.46 | H24: =H12/150 -> 0.14666667
D25: Easiest and fastest process for opening an account or ordering a physical debit card | E25: =E13/150 -> 0.13333333 | F25: =F13/150 -> 0.29333333 | G25: =G13/150 -> 0.39333333 | H25: =H13/150 -> 0.17333333
D26: Best app for international payments | E26: =E14/150 -> 0.22 | F26: =F14/150 -> 0.18 | G26: =G14/150 -> 0.32 | H26: =H14/150 -> 0.24666667

Sheet Sheet1
A1: previous app | C1: Favorite App
C3: easypaisa | D3: sadapay | E3: nayapay | F3: jazzcash
B4: easypaisa | D4: =COUNTIFS($I$2:$I$151,$F4,$G$2:$G$151,D$249) -> 7 | E4: =COUNTIFS($I$2:$I$151,$F4,$G$2:$G$151,E$249) -> 7 | F4: =COUNTIFS($I$2:$I$151,$F4,$G$2:$G$151,F$249) -> 26
B5: sadapay | C5: =COUNTIFS($I$2:$I$151,$F5,$G$2:$G$151,C$249) -> 4 | E5: =COUNTIFS($I$2:$I$151,$F5,$G$2:$G$151,E$249) -> 2 | F5: =COUNTIFS($I$2:$I$151,$F5,$G$2:$G$151,F$249) -> 3
B6: nayapay | C6: =COUNTIFS($I$2:$I$151,$F6,$G$2:$G$151,C$249) -> 4 | D6: =COUNTIFS($I$2:$I$151,$F6,$G$2:$G$151,D$249) -> 0 | F6: =COUNTIFS($I$2:$I$151,$F6,$G$2:$G$151,F$249) -> 5
B7: jazzcash | C7: =COUNTIFS($I$2:$I$151,$F7,$G$2:$G$151,C$249) -> 0 | D7: =COUNTIFS($I$2:$I$151,$F7,$G$2:$G$151,D$249) -> 0 | E7: =COUNTIFS($I$2:$I$151,$F7,$G$2:$G$151,E$249) -> 0

Sheet NPS
D6: NPS | E6: {=TRANSPOSE(_xlfn.UNIQUE(SINGLE_RESPONSES[FAVORITE]))} -> easypaisa | F6: sadapay | G6: nayapay | H6: jazzcash
D7: 0 | E7: =COUNTIFS(SINGLE_RESPONSES[FAVORITE],NPS!E$6,SINGLE_RESPONSES[NPS],NPS!$D7) -> 0 | F7: =COUNTIFS(SINGLE_RESPONSES[FAVORITE],NPS!F$6,SINGLE_RESPONSES[NPS],NPS!$D7) -> 0 | G7: =COUNTIFS(SINGLE_RESPONSES[FAVORITE],NPS!G$6,SINGLE_RESPONSES[NPS],NPS!$D7) -> 0 | H7: =COUNTIFS(SINGLE_RESPONSES[FAVORITE],NPS!H$6,SINGLE_RESPONSES[NPS],NPS!$D7) -> 0
D8: 1 | E8: =COUNTIFS(SINGLE_RESPONSES[FAVORITE],NPS!E$6,SINGLE_RESPONSES[NPS],NPS!$D8) -> 1 | F8: =COUNTIFS(SINGLE_RESPONSES[FAVORITE],NPS!F$6,SINGLE_RESPONSES[NPS],NPS!$D8) -> 1 | G8: =COUNTIFS(SINGLE_RESPONSES[FAVORITE],NPS!G$6,SINGLE_RESPONSES[NPS],NPS!$D8) -> 1 | H8: =COUNTIFS(SINGLE_RESPONSES[FAVORITE],NPS!H$6,SINGLE_RESPONSES[NPS],NPS!$D8) -> 5
D9: 2 | E9: =COUNTIFS(SINGLE_RESPONSES[FAVORITE],NPS!E$6,SINGLE_RESPONSES[NPS],NPS!$D9) -> 0 | F9: =COUNTIFS(SINGLE_RESPONSES[FAVORITE],NPS!F$6,SINGLE_RESPONSES[NPS],NPS!$D9) -> 1 | G9: =COUNTIFS(SINGLE_RESPONSES[FAVORITE],NPS!G$6,SINGLE_RESPONSES[NPS],NPS!$D9) -> 0 | H9: =COUNTIFS(SINGLE_RESPONSES[FAVORITE],NPS!H$6,SINGLE_RESPONSES[NPS],NPS!$D9) -> 1
D10: 3 | E10: =COUNTIFS(SINGLE_RESPONSES[FAVORITE],NPS!E$6,SINGLE_RESPONSES[NPS],NPS!$D10) -> 2 | F10: =COUNTIFS(SINGLE_RESPONSES[FAVORITE],NPS!F$6,SINGLE_RESPONSES[NPS],NPS!$D10) -> 1 | G10: =COUNTIFS(SINGLE_RESPONSES[FAVORITE],NPS!G$6,SINGLE_RESPONSES[NPS],NPS!$D10) -> 0 | H10: =COUNTIFS(SINGLE_RESPONSES[FAVORITE],NPS!H$6,SINGLE_RESPONSES[NPS],NPS!$D10) -> 2
D11: 4 | E11: =COUNTIFS(SINGLE_RESPONSES[FAVORITE],NPS!E$6,SINGLE_RESPONSES[NPS],NPS!$D11) -> 1 | F11: =COUNTIFS(SINGLE_RESPONSES[FAVORITE],NPS!F$6,SINGLE_RESPONSES[NPS],NPS!$D11) -> 0 | G11: =COUNTIFS(SINGLE_RESPONSES[FAVORITE],NPS!G$6,SINGLE_RESPONSES[NPS],NPS!$D11) -> 0 | H11: =COUNTIFS(SINGLE_RESPONSES[FAVORITE],NPS!H$6,SINGLE_RESPONSES[NPS],NPS!$D11) -> 3
D12: 5 | E12: =COUNTIFS(SINGLE_RESPONSES[FAVORITE],NPS!E$6,SINGLE_RESPONSES[NPS],NPS!$D12) -> 0 | F12: =COUNTIFS(SINGLE_RESPONSES[FAVORITE],NPS!F$6,SINGLE_RESPONSES[NPS],NPS!$D12) -> 1 | G12: =COUNTIFS(SINGLE_RESPONSES[FAVORITE],NPS!G$6,SINGLE_RESPONSES[NPS],NPS!$D12) -> 1 | H12: =COUNTIFS(SINGLE_RESPONSES[FAVORITE],NPS!H$6,SINGLE_RESPONSES[NPS],NPS!$D12) -> 5
D13: 6 | E13: =COUNTIFS(SINGLE_RESPONSES[FAVORITE],NPS!E$6,SINGLE_RESPONSES[NPS],NPS!$D13) -> 1 | F13: =COUNTIFS(SINGLE_RESPONSES[FAVORITE],NPS!F$6,SINGLE_RESPONSES[NPS],NPS!$D13) -> 2 | G13: =COUNTIFS(SINGLE_RESPONSES[FAVORITE],NPS!G$6,SINGLE_RESPONSES[NPS],NPS!$D13) -> 0 | H13: =COUNTIFS(SINGLE_RESPONSES[FAVORITE],NPS!H$6,SINGLE_RESPONSES[NPS],NPS!$D13) -> 3
D14: 7 | E14: =COUNTIFS(SINGLE_RESPONSES[FAVORITE],NPS!E$6,SINGLE_RESPONSES[NPS],NPS!$D14) -> 6 | F14: =COUNTIFS(SINGLE_RESPONSES[FAVORITE],NPS!F$6,SINGLE_RESPONSES[NPS],NPS!$D14) -> 1 | G14: =COUNTIFS(SINGLE_RESPONSES[FAVORITE],NPS!G$6,SINGLE_RESPONSES[NPS],NPS!$D14) -> 4 | H14: =COUNTIFS(SINGLE_RESPONSES[FAVORITE],NPS!H$6,SINGLE_RESPONSES[NPS],NPS!$D14) -> 7
D15: 8 | E15: =COUNTIFS(SINGLE_RESPONSES[FAVORITE],NPS!E$6,SINGLE_RESPONSES[NPS],NPS!$D15) -> 12 | F15: =COUNTIFS(SINGLE_RESPONSES[FAVORITE],NPS!F$6,SINGLE_RESPONSES[NPS],NPS!$D15) -> 4 | G15: =COUNTIFS(SINGLE_RESPONSES[FAVORITE],NPS!G$6,SINGLE_RESPONSES[NPS],NPS!$D15) -> 2 | H15: =COUNTIFS(SINGLE_RESPONSES[FAVORITE],NPS!H$6,SINGLE_RESPONSES[NPS],NPS!$D15) -> 14
D16: 9 | E16: =COUNTIFS(SINGLE_RESPONSES[FAVORITE],NPS!E$6,SINGLE_RESPONSES[NPS],NPS!$D16) -> 9 | F16: =COUNTIFS(SINGLE_RESPONSES[FAVORITE],NPS!F$6,SINGLE_RESPONSES[NPS],NPS!$D16) -> 3 | G16: =COUNTIFS(SINGLE_RESPONSES[FAVORITE],NPS!G$6,SINGLE_RESPONSES[NPS],NPS!$D16) -> 3 | H16: =COUNTIFS(SINGLE_RESPONSES[FAVORITE],NPS!H$6,SINGLE_RESPONSES[NPS],NPS!$D16) -> 6
D17: 10 | E17: =COUNTIFS(SINGLE_RESPONSES[FAVORITE],NPS!E$6,SINGLE_RESPONSES[NPS],NPS!$D17) -> 11 | F17: =COUNTIFS(SINGLE_RESPONSES[FAVORITE],NPS!F$6,SINGLE_RESPONSES[NPS],NPS!$D17) -> 4 | G17: =COUNTIFS(SINGLE_RESPONSES[FAVORITE],NPS!G$6,SINGLE_RESPONSES[NPS],NPS!$D17) -> 13 | H17: =COUNTIFS(SINGLE_RESPONSES[FAVORITE],NPS!H$6,SINGLE_RESPONSES[NPS],NPS!$D17) -> 19
E18: =SUM(E7:E17) -> 43 | F18: =SUM(F7:F17) -> 18 | G18: =SUM(G7:G17) -> 24 | H18: =SUM(H7:H17) -> 65
D21: Detractors | E21: =SUM(E7:E12) -> 4 | F21: =SUM(F7:F12) -> 4 | G21: =SUM(G7:G12) -> 2 | H21: =SUM(H7:H12) -> 16
D22: Neutral | E22: =E13+E14 -> 7 | F22: =F13+F14 -> 3 | G22: =G13+G14 -> 4 | H22: =H13+H14 -> 10
D23: Promoters | E23: =SUM(E15:E17) -> 32 | F23: =SUM(F15:F17) -> 11 | G23: =SUM(G15:G17) -> 18 | H23: =SUM(H15:H17) -> 39
D27: NPS | E27: =E23-E21 -> 28 | F27: =F23-F21 -> 7 | G27: =G23-G21 -> 16 | H27: =H23-H21 -> 23
E28: =E27/150 -> 0.18666667 | F28: =F27/150 -> 0.046666667 | G28: =G27/150 -> 0.10666667 | H28: =H27/150 -> 0.15333333

Sheet Analysis for alternate apps
A3: Count of Alternate App | B3: Column Labels
A4: Row Labels | B4: bank app | C4: easypaisa | D4: jazzcash | E4: nayapay | F4: none | G4: sadapay | H4: Grand Total
A5: easypaisa | B5: 4 | C5: 6 | D5: 15 | E5: 7 | G5: 11 | H5: 43
A6: jazzcash | B6: 11 | C6: 27 | D6: 8 | E6: 13 | F6: 1 | G6: 5 | H6: 65
A7: nayapay | B7: 6 | C7: 6 | D7: 7 | E7: 3 | G7: 2 | H7: 24
A8: sadapay | B8: 3 | C8: 4 | D8: 7 | E8: 3 | F8: 1 | H8: 18
A9: Grand Total | B9: 24 | C9: 43 | D9: 37 | E9: 26 | F9: 2 | G9: 18 | H9: 150
B10: Alternate App
A11: Favorite App | B11: bank app | C11: easypaisa | D11: jazzcash | E11: nayapay | F11: none | G11: sadapay
A12: easypaisa | B12: 4 | D12: 15 | E12: 7 | F12: 0 | G12: 11
A13: jazzcash | B13: 11 | C13: 27 | E13: 13 | F13: 1 | G13: 5
A14: nayapay | B14: 6 | C14: 6 | D14: 7 | G14: 2
A15: sadapay | B15: 3 | C15: 4 | D15: 7 | E15: 3 | F15: 1
A16: Grand total | B16: 24 | C16: 43 | D16: 30 | E16: 23 | F16: 2 | G16: 16

Sheet CURRENT USAGE_Data
A1: Index | B1: APP
A2: 1 | B2: easypaisa
A3: 2 | B3: easypaisa
A4: 3 | B4: sadapay
A5: 4 | B5: easypaisa
A6: 5 | B6: easypaisa
A7: 6 | B7: easypaisa
A8: 7 | B8: jazzcash
A9: 8 | B9: easypaisa
A10: 9 | B10: jazzcash
A11: 10 | B11: nayapay
A12: 11 | B12: jazzcash
A13: 12 | B13: jazzcash
... A255: 254 | B255: nayapay

Sheet Awareness_data
A1: Application(Awareness) | B1: Value
A2: jazzcash | B2: 1
A3: easypaisa | B3: 1
A4: sadapay | B4: 1
A5: easypaisa | B5: 1
A6: sadapay | B6: 1
A7: jazzcash | B7: 1
A8: easypaisa | B8: 1
A9: nayapay | B9: 1
A10: jazzcash | B10: 1
A11: easypaisa | B11: 1
A12: sadapay | B12: 1
A13: nayapay | B13: 1
... A331: nayapay | B331: 1

Sheet Engineered_Awareness_data
D1: TOM | E1: EVER USED | F1: CURRENT USAGE | G1: jazzcash | H1: easypaisa | I1: sadapay | J1: nayapay
D2: easypaisa | E2: jazzcash,easypaisa,sadapay | F2: easypaisa | G2: =IF(OR(ISNUMBER(SEARCH("jazzcash", D2)), ISNUMBER(SEARCH("jazzcash", E2)), ISNUMBER(SEARCH("jazzcash", F2))), 1, 0) -> 1 | H2: =IF(OR(ISNUMBER(SEARCH("easypaisa", D2)), ISNUMBER(SEARCH("easypaisa", E2)), ISNUMBER(SEARCH("easypaisa", F2))), 1, 0) -> 1 | I2: =IF(OR(ISNUMBER(SEARCH("sadapay", D2)), ISNUMBER(SEARCH("sadapay", E2)), ISNUMBER(SEARCH("sadapay", F2))), 1, 0) -> 1 | J2: =IF(OR(ISNUMBER(SEARCH("nayapay", D2)), ISNUMBER(SEARCH("nayapay", E2)), ISNUMBER(SEARCH("nayapay", F2))), 1, 0) -> 0
D3: easypaisa | E3: easypaisa | F3: easypaisa | G3: =IF(OR(ISNUMBER(SEARCH("jazzcash", D3)), ISNUMBER(SEARCH("jazzcash", E3)), ISNUMBER(SEARCH("jazzcash", F3))), 1, 0) -> 0 | H3: =IF(OR(ISNUMBER(SEARCH("easypaisa", D3)), ISNUMBER(SEARCH("easypaisa", E3)), ISNUMBER(SEARCH("easypaisa", F3))), 1, 0) -> 1 | I3: =IF(OR(ISNUMBER(SEARCH("sadapay", D3)), ISNUMBER(SEARCH("sadapay", E3)), ISNUMBER(SEARCH("sadapay", F3))), 1, 0) -> 0 | J3: =IF(OR(ISNUMBER(SEARCH("nayapay", D3)), ISNUMBER(SEARCH("nayapay", E3)), ISNUMBER(SEARCH("nayapay", F3))), 1, 0) -> 0
D4: sadapay | E4: sadapay | F4: sadapay | G4: =IF(OR(ISNUMBER(SEARCH("jazzcash", D4)), ISNUMBER(SEARCH("jazzcash", E4)), ISNUMBER(SEARCH("jazzcash", F4))), 1, 0) -> 0 | H4: =IF(OR(ISNUMBER(SEARCH("easypaisa", D4)), ISNUMBER(SEARCH("easypaisa", E4)), ISNUMBER(SEARCH("easypaisa", F4))), 1, 0) -> 0 | I4: =IF(OR(ISNUMBER(SEARCH("sadapay", D4)), ISNUMBER(SEARCH("sadapay", E4)), ISNUMBER(SEARCH("sadapay", F4))), 1, 0) -> 1 | J4: =IF(OR(ISNUMBER(SEARCH("nayapay", D4)), ISNUMBER(SEARCH("nayapay", E4)), ISNUMBER(SEARCH("nayapay", F4))), 1, 0) -> 0
D5: easypaisa | E5: jazzcash,easypaisa,nayapay | F5: easypaisa | G5: =IF(OR(ISNUMBER(SEARCH("jazzcash", D5)), ISNUMBER(SEARCH("jazzcash", E5)), ISNUMBER(SEARCH("jazzcash", F5))), 1, 0) -> 1 | H5: =IF(OR(ISNUMBER(SEARCH("easypaisa", D5)), ISNUMBER(SEARCH("easypaisa", E5)), ISNUMBER(SEARCH("easypaisa", F5))), 1, 0) -> 1 | I5: =IF(OR(ISNUMBER(SEARCH("sadapay", D5)), ISNUMBER(SEARCH("sadapay", E5)), ISNUMBER(SEARCH("sadapay", F5))), 1, 0) -> 0 | J5: =IF(OR(ISNUMBER(SEARCH("nayapay", D5)), ISNUMBER(SEARCH("nayapay", E5)), ISNUMBER(SEARCH("nayapay", F5))), 1, 0) -> 1
D6: easypaisa | E6: jazzcash,easypaisa,sadapay,nayapay | F6: easypaisa | G6: =IF(OR(ISNUMBER(SEARCH("jazzcash", D6)), ISNUMBER(SEARCH("jazzcash", E6)), ISNUMBER(SEARCH("jazzcash", F6))), 1, 0) -> 1 | H6: =IF(OR(ISNUMBER(SEARCH("easypaisa", D6)), ISNUMBER(SEARCH("easypaisa", E6)), ISNUMBER(SEARCH("easypaisa", F6))), 1, 0) -> 1 | I6: =IF(OR(ISNUMBER(SEARCH("sadapay", D6)), ISNUMBER(SEARCH("sadapay", E6)), ISNUMBER(SEARCH("sadapay", F6))), 1, 0) -> 1 | J6: =IF(OR(ISNUMBER(SEARCH("nayapay", D6)), ISNUMBER(SEARCH("nayapay", E6)), ISNUMBER(SEARCH("nayapay", F6))), 1, 0) -> 1
D7: jazzcash | E7: easypaisa | F7: easypaisa | G7: =IF(OR(ISNUMBER(SEARCH("jazzcash", D7)), ISNUMBER(SEARCH("jazzcash", E7)), ISNUMBER(SEARCH("jazzcash", F7))), 1, 0) -> 1 | H7: =IF(OR(ISNUMBER(SEARCH("easypaisa", D7)), ISNUMBER(SEARCH("easypaisa", E7)), ISNUMBER(SEARCH("easypaisa", F7))), 1, 0) -> 1 | I7: =IF(OR(ISNUMBER(SEARCH("sadapay", D7)), ISNUMBER(SEARCH("sadapay", E7)), ISNUMBER(SEARCH("sadapay", F7))), 1, 0) -> 0 | J7: =IF(OR(ISNUMBER(SEARCH("nayapay", D7)), ISNUMBER(SEARCH("nayapay", E7)), ISNUMBER(SEARCH("nayapay", F7))), 1, 0) -> 0
D8: easypaisa | E8: easypaisa | F8: jazzcash,easypaisa | G8: =IF(OR(ISNUMBER(SEARCH("jazzcash", D8)), ISNUMBER(SEARCH("jazzcash", E8)), ISNUMBER(SEARCH("jazzcash", F8))), 1, 0) -> 1 | H8: =IF(OR(ISNUMBER(SEARCH("easypaisa", D8)), ISNUMBER(SEARCH("easypaisa", E8)), ISNUMBER(SEARCH("easypaisa", F8))), 1, 0) -> 1 | I8: =IF(OR(ISNUMBER(SEARCH("sadapay", D8)), ISNUMBER(SEARCH("sadapay", E8)), ISNUMBER(SEARCH("sadapay", F8))), 1, 0) -> 0 | J8: =IF(OR(ISNUMBER(SEARCH("nayapay", D8)), ISNUMBER(SEARCH("nayapay", E8)), ISNUMBER(SEARCH("nayapay", F8))), 1, 0) -> 0
D9: nayapay | E9: jazzcash,sadapay,nayapay | F9: jazzcash,nayapay | G9: =IF(OR(ISNUMBER(SEARCH("jazzcash", D9)), ISNUMBER(SEARCH("jazzcash", E9)), ISNUMBER(SEARCH("jazzcash", F9))), 1, 0) -> 1 | H9: =IF(OR(ISNUMBER(SEARCH("easypaisa", D9)), ISNUMBER(SEARCH("easypaisa", E9)), ISNUMBER(SEARCH("easypaisa", F9))), 1, 0) -> 0 | I9: =IF(OR(ISNUMBER(SEARCH("sadapay", D9)), ISNUMBER(SEARCH("sadapay", E9)), ISNUMBER(SEARCH("sadapay", F9))), 1, 0) -> 1 | J9: =IF(OR(ISNUMBER(SEARCH("nayapay", D9)), ISNUMBER(SEARCH("nayapay", E9)), ISNUMBER(SEARCH("nayapay", F9))), 1, 0) -> 1
D10: jazzcash | E10: jazzcash,sadapay | F10: jazzcash | G10: =IF(OR(ISNUMBER(SEARCH("jazzcash", D10)), ISNUMBER(SEARCH("jazzcash", E10)), ISNUMBER(SEARCH("jazzcash", F10))), 1, 0) -> 1 | H10: =IF(OR(ISNUMBER(SEARCH("easypaisa", D10)), ISNUMBER(SEARCH("easypaisa", E10)), ISNUMBER(SEARCH("easypaisa", F10))), 1, 0) -> 0 | I10: =IF(OR(ISNUMBER(SEARCH("sadapay", D10)), ISNUMBER(SEARCH("sadapay", E10)), ISNUMBER(SEARCH("sadapay", F10))), 1, 0) -> 1 | J10: =IF(OR(ISNUMBER(SEARCH("nayapay", D10)), ISNUMBER(SEARCH("nayapay", E10)), ISNUMBER(SEARCH("nayapay", F10))), 1, 0) -> 0
D11: sadapay | E11: sadapay | F11: jazzcash,easypaisa,sadapay | G11: =IF(OR(ISNUMBER(SEARCH("jazzcash", D11)), ISNUMBER(SEARCH("jazzcash", E11)), ISNUMBER(SEARCH("jazzcash", F11))), 1, 0) -> 1 | H11: =IF(OR(ISNUMBER(SEARCH("easypaisa", D11)), ISNUMBER(SEARCH("easypaisa", E11)), ISNUMBER(SEARCH("easypaisa", F11))), 1, 0) -> 1 | I11: =IF(OR(ISNUMBER(SEARCH("sadapay", D11)), ISNUMBER(SEARCH("sadapay", E11)), ISNUMBER(SEARCH("sadapay", F11))), 1, 0) -> 1 | J11: =IF(OR(ISNUMBER(SEARCH("nayapay", D11)), ISNUMBER(SEARCH("nayapay", E11)), ISNUMBER(SEARCH("nayapay", F11))), 1, 0) -> 0
D12: jazzcash | E12: jazzcash,nayapay | F12: jazzcash,nayapay | G12: =IF(OR(ISNUMBER(SEARCH("jazzcash", D12)), ISNUMBER(SEARCH("jazzcash", E12)), ISNUMBER(SEARCH("jazzcash", F12))), 1, 0) -> 1 | H12: =IF(OR(ISNUMBER(SEARCH("easypaisa", D12)), ISNUMBER(SEARCH("easypaisa", E12)), ISNUMBER(SEARCH("easypaisa", F12))), 1, 0) -> 0 | I12: =IF(OR(ISNUMBER(SEARCH("sadapay", D12)), ISNUMBER(SEARCH("sadapay", E12)), ISNUMBER(SEARCH("sadapay", F12))), 1, 0) -> 0 | J12: =IF(OR(ISNUMBER(SEARCH("nayapay", D12)), ISNUMBER(SEARCH("nayapay", E12)), ISNUMBER(SEARCH("nayapay", F12))), 1, 0) -> 1
D13: jazzcash | E13: jazzcash,easypaisa,sadapay,nayapay | F13: easypaisa | G13: =IF(OR(ISNUMBER(SEARCH("jazzcash", D13)), ISNUMBER(SEARCH("jazzcash", E13)), ISNUMBER(SEARCH("jazzcash", F13))), 1, 0) -> 1 | H13: =IF(OR(ISNUMBER(SEARCH("easypaisa", D13)), ISNUMBER(SEARCH("easypaisa", E13)), ISNUMBER(SEARCH("easypaisa", F13))), 1, 0) -> 1 | I13: =IF(OR(ISNUMBER(SEARCH("sadapay", D13)), ISNUMBER(SEARCH("sadapay", E13)), ISNUMBER(SEARCH("sadapay", F13))), 1, 0) -> 1 | J13: =IF(OR(ISNUMBER(SEARCH("nayapay", D13)), ISNUMBER(SEARCH("nayapay", E13)), ISNUMBER(SEARCH("nayapay", F13))), 1, 0) -> 1
... D151: jazzcash | E151: jazzcash,easypaisa,sadapay,nayapay | F151: jazzcash,sadapay,nayapay | G151: =IF(OR(ISNUMBER(SEARCH("jazzcash", D151)), ISNUMBER(SEARCH("jazzcash", E151)), ISNUMBER(SEARCH("jazzcash", F151))), 1, 0) -> 1 | H151: =IF(OR(ISNUMBER(SEARCH("easypaisa", D151)), ISNUMBER(SEARCH("easypaisa", E151)), ISNUMBER(SEARCH("easypaisa", F151))), 1, 0) -> 1 | I151: =IF(OR(ISNUMBER(SEARCH("sadapay", D151)), ISNUMBER(SEARCH("sadapay", E151)), ISNUMBER(SEARCH("sadapay", F151))), 1, 0) -> 1 | J151: =IF(OR(ISNUMBER(SEARCH("nayapay", D151)), ISNUMBER(SEARCH("nayapay", E151)), ISNUMBER(SEARCH("nayapay", F151))), 1, 0) -> 1
G152: =SUM(G2:G151) -> 114 | H152: =SUM(H2:H151) -> 100 | I152: =SUM(I2:I151) -> 61 | J152: =SUM(J2:J151) -> 55
G154: =G152/150 -> 0.76 | H154: =H152/150 -> 0.66666667 | I154: =I152/150 -> 0.40666667 | J154: =J152/150 -> 0.36666667

Sheet EVER USED_Data
A1: Index | B1: APP
A2: 1 | B2: jazzcash
A3: 2 | B3: easypaisa
A4: 3 | B4: sadapay
A5: 4 | B5: easypaisa
A6: 5 | B6: sadapay
A7: 6 | B7: jazzcash
A8: 7 | B8: easypaisa
A9: 8 | B9: nayapay
A10: 9 | B10: jazzcash
A11: 10 | B11: easypaisa
A12: 11 | B12: sadapay
A13: 12 | B13: nayapay
... A299: 298 | B299: nayapay

Sheet IMAGERY_Data
A1: Index | B1: IMAGERY | C1: APP
A2: 1 | B2: Best app interface and user experience (UX) | C2: sadapay
A3: 1 | B3: Most reliable (least likely to have server/network down issues) | C3: easypaisa
A4: 1 | B4: Offers the best discounts, deals, and cashbacks | C4: jazzcash
A5: 1 | B5: Good customer service and quick issue resolution | C5: sadapay
A6: 1 | B6: Lowest transaction fees and free inter-bank fund transfers (IBFT) | C6: easypaisa
A7: 1 | B7: Strongest security features | C7: easypaisa
A8: 1 | B8: Easiest and fastest process for opening an account or ordering a physical debit card | C8: easypaisa
A9: 1 | B9: Best app for international payments | C9: easypaisa
A10: 2 | B10: Best app interface and user experience (UX) | C10: easypaisa
A11: 2 | B11: Most reliable (least likely to have server/network down issues) | C11: easypaisa
A12: 2 | B12: Offers the best discounts, deals, and cashbacks | C12: easypaisa
A13: 2 | B13: Good customer service and quick issue resolution | C13: easypaisa
... A1197: 150 | B1197: Best app for international payments | C1197: nayapay

Sheet SINGLE_RESPONSES
A1: Name | B1: Gender | C1: Age | D1: coding | E1: City | F1: TOM | G1: FAVORITE | H1: Using since | I1: Previous Brand | J1: Reasons for switching | K1: Future intent | L1: Reasons for keep using | M1: NPS | N1: Alternate App | O1: 5.1) Have you seen the advertisement above on TV recently or not? | P1: 5.2 ) What digital payment app was this ad for? | Q1: 5.3) In your own words, what was the main message of this ad? (Please be specific; avoid general answers like 'it is a good app.' | R1: 5.4) To what extent did you like this ad?
A2: Gulfam | B2: Male | C2: 30 - 41 | D2: {=_xlfn.IFS(SINGLE_RESPONSES[[#This Row],[Age]]="18 - 29",1, SINGLE_RESPONSES[[#This Row],[Age]]="30 - 41",2,SINGLE_RESPONSES[[#This Row],[Age]]="42 -53",3, SINGLE_RESPONSES[[#This Row],[Age]]="54 - 65",4, SINGLE_RESPONSES[[#This Row],[Age]]="66 and above",5)} -> 2 | E2: Lahore | F2: easypaisa | G2: easypaisa | H2: 6 | I2: sadapay | J2: account blockage and trust issues | K2: Yes | L2: easier to manage small transactions and payments like payment of bills etc | M2: 9 | N2: jazzcash | O2: No | P2: easypaisa | Q2: have not seen this ad | R2: 1
A3: waleed | B3: Male | C3: 18 - 29 | D3: {=_xlfn.IFS(SINGLE_RESPONSES[[#This Row],[Age]]="18 - 29",1, SINGLE_RESPONSES[[#This Row],[Age]]="30 - 41",2,SINGLE_RESPONSES[[#This Row],[Age]]="42 -53",3, SINGLE_RESPONSES[[#This Row],[Age]]="54 - 65",4, SINGLE_RESPONSES[[#This Row],[Age]]="66 and above",5)} -> 1 | E3: Lahore | F3: easypaisa | G3: easypaisa | H3: 4 | I3: easypaisa | J3: Not switched | K3: Yes | L3: Best user interface and user experience | M3: 9 | N3: bankingapp | O3: Yes | P3: easypaisa | Q3: You can transfer money from anywhere in your easy paisa account and it'll be transferred in your account immediately without any disruption | R3: 5
A4: Talha | B4: Male | C4: 18 - 29 | D4: {=_xlfn.IFS(SINGLE_RESPONSES[[#This Row],[Age]]="18 - 29",1, SINGLE_RESPONSES[[#This Row],[Age]]="30 - 41",2,SINGLE_RESPONSES[[#This Row],[Age]]="42 -53",3, SINGLE_RESPONSES[[#This Row],[Age]]="54 - 65",4, SINGLE_RESPONSES[[#This Row],[Age]]="66 and above",5)} -> 1 | E4: Lahore | F4: sadapay | G4: sadapay | H4: 4 | I4: easypaisa | J4: Easy to assess | K4: Yes | L4: Easy to assess | M4: 10 | N4: bankingapp | O4: Yes | P4: easypaisa | Q4: Easy to transfer | R4: 10
A5: Jawad Waseem | B5: Male | C5: 18 - 29 | D5: {=_xlfn.IFS(SINGLE_RESPONSES[[#This Row],[Age]]="18 - 29",1, SINGLE_RESPONSES[[#This Row],[Age]]="30 - 41",2,SINGLE_RESPONSES[[#This Row],[Age]]="42 -53",3, SINGLE_RESPONSES[[#This Row],[Age]]="54 - 65",4, SINGLE_RESPONSES[[#This Row],[Age]]="66 and above",5)} -> 1 | E5: Lahore | F5: easypaisa | G5: easypaisa | H5: 7 | I5: nayapay | J5: More options | K5: Yes | L5: Connectivity and | M5: 7 | N5: nayapay | O5: Yes | P5: easypaisa | Q5: Easy transfer | R5: 5
A6: Abdullah | B6: Male | C6: 18 - 29 | D6: {=_xlfn.IFS(SINGLE_RESPONSES[[#This Row],[Age]]="18 - 29",1, SINGLE_RESPONSES[[#This Row],[Age]]="30 - 41",2,SINGLE_RESPONSES[[#This Row],[Age]]="42 -53",3, SINGLE_RESPONSES[[#This Row],[Age]]="54 - 65",4, SINGLE_RESPONSES[[#This Row],[Age]]="66 and above",5)} -> 1 | E6: Lahore | F6: easypaisa | G6: easypaisa | H6: 6 | I6: jazzcash | J6: Bad service | K6: Yes | L6: Fast service | M6: 8 | N6: jazzcash | O6: Yes | P6: easypaisa | Q6: Make digital wallet for small transactions | R6: 7
A7: Muhammad saad ahmad | B7: Male | C7: 18 - 29 | D7: {=_xlfn.IFS(SINGLE_RESPONSES[[#This Row],[Age]]="18 - 29",1, SINGLE_RESPONSES[[#This Row],[Age]]="30 - 41",2,SINGLE_RESPONSES[[#This Row],[Age]]="42 -53",3, SINGLE_RESPONSES[[#This Row],[Age]]="54 - 65",4, SINGLE_RESPONSES[[#This Row],[Age]]="66 and above",5)} -> 1 | E7: Lahore | F7: jazzcash | G7: easypaisa | H7: 5 | I7: nayapay | J7: Wasn't reliable | K7: Yes | L7: Easy to use | M7: 9 | N7: nayapay | O7: No | P7: i have not seen this ad | Q7: That the transfer of money can be made remotely and easily | R7: 10
A8: Mubashir hassan | B8: Male | C8: 18 - 29 | D8: {=_xlfn.IFS(SINGLE_RESPONSES[[#This Row],[Age]]="18 - 29",1, SINGLE_RESPONSES[[#This Row],[Age]]="30 - 41",2,SINGLE_RESPONSES[[#This Row],[Age]]="42 -53",3, SINGLE_RESPONSES[[#This Row],[Age]]="54 - 65",4, SINGLE_RESPONSES[[#This Row],[Age]]="66 and above",5)} -> 1 | E8: Lahore | F8: easypaisa | G8: easypaisa | H8: 7 | I8: jazzcash | J8: User experience | K8: Yes | L8: User experience and user interface | M8: 7 | N8: bankingapp | O8: Yes | P8: jazzcash | Q8: They communicate. With customers... | R8: 7
A9: Ayesha | B9: Female | C9: 18 - 29 | D9: {=_xlfn.IFS(SINGLE_RESPONSES[[#This Row],[Age]]="18 - 29",1, SINGLE_RESPONSES[[#This Row],[Age]]="30 - 41",2,SINGLE_RESPONSES[[#This Row],[Age]]="42 -53",3, SINGLE_RESPONSES[[#This Row],[Age]]="54 - 65",4, SINGLE_RESPONSES[[#This Row],[Age]]="66 and above",5)} -> 1 | E9: Lahore | F9: nayapay | G9: nayapay | H9: 7 | I9: jazzcash | J9: It's secure and easy to use. | K9: Yes | L9: It's easy to use. | M9: 9 | N9: jazzcash | O9: Maybe | P9: easypaisa | Q9: Digital wallet apps awareness | R9: 10
A10: Kainat | B10: Female | C10: 18 - 29 | D10: {=_xlfn.IFS(SINGLE_RESPONSES[[#This Row],[Age]]="18 - 29",1, SINGLE_RESPONSES[[#This Row],[Age]]="30 - 41",2,SINGLE_RESPONSES[[#This Row],[Age]]="42 -53",3, SINGLE_RESPONSES[[#This Row],[Age]]="54 - 65",4, SINGLE_RESPONSES[[#This Row],[Age]]="66 and above",5)} -> 1 | E10: Lahore | F10: jazzcash | G10: jazzcash | H10: 4 | I10: jazzcash | J10: Not switched | K10: Yes | L10: Easily manageable and reliable | M10: 10 | N10: bankingapp | O10: Maybe | P10: i have not seen this ad | Q10: I haven't seen this ad | R10: 1
A11: Muhammad Danish Zafar | B11: Male | C11: 18 - 29 | D11: {=_xlfn.IFS(SINGLE_RESPONSES[[#This Row],[Age]]="18 - 29",1, SINGLE_RESPONSES[[#This Row],[Age]]="30 - 41",2,SINGLE_RESPONSES[[#This Row],[Age]]="42 -53",3, SINGLE_RESPONSES[[#This Row],[Age]]="54 - 65",4, SINGLE_RESPONSES[[#This Row],[Age]]="66 and above",5)} -> 1 | E11: Lahore | F11: sadapay | G11: sadapay | H11: 7 | I11: easypaisa | J11: Most of the time servers down | K11: Yes | L11: International transactions | M11: 8 | N11: jazzcash | O11: Maybe | P11: easypaisa | Q11: Payment transfer | R11: 5
A12: Hassan Jehangir | B12: Male | C12: 18 - 29 | D12: {=_xlfn.IFS(SINGLE_RESPONSES[[#This Row],[Age]]="18 - 29",1, SINGLE_RESPONSES[[#This Row],[Age]]="30 - 41",2,SINGLE_RESPONSES[[#This Row],[Age]]="42 -53",3, SINGLE_RESPONSES[[#This Row],[Age]]="54 - 65",4, SINGLE_RESPONSES[[#This Row],[Age]]="66 and above",5)} -> 1 | E12: Lahore | F12: jazzcash | G12: jazzcash | H12: 4 | I12: easypaisa | J12: Easy to transfer money instantly | K12: Yes | L12: Instant money transfer and good UI | M12: 10 | N12: nayapay | O12: No | P12: i have not seen this ad | Q12: No idea | R12: 1
A13: Rayyan Amin | B13: Female | C13: 18 - 29 | D13: {=_xlfn.IFS(SINGLE_RESPONSES[[#This Row],[Age]]="18 - 29",1, SINGLE_RESPONSES[[#This Row],[Age]]="30 - 41",2,SINGLE_RESPONSES[[#This Row],[Age]]="42 -53",3, SINGLE_RESPONSES[[#This Row],[Age]]="54 - 65",4, SINGLE_RESPONSES[[#This Row],[Age]]="66 and above",5)} -> 1 | E13: Lahore | F13: jazzcash | G13: easypaisa | H13: 5 | I13: jazzcash | J13: Better services | K13: Yes | L13: Easy transactions | M13: 8 | N13: sadapay | O13: No | P13: easypaisa | Q13: Cheap and easy | R13: 9
... A23: Shoaib Ahmad | B23: Male | C23: 18 - 29 | D23: {=_xlfn.IFS(SINGLE_RESPONSES[[#This Row],[Age]]="18 - 29",1, SINGLE_RESPONSES[[#This Row],[Age]]="30 - 41",2,SINGLE_RESPONSES[[#This Row],[Age]]="42 -53",3, SINGLE_RESPONSES[[#This Row],[Age]]="54 - 65",4, SINGLE_RESPONSES[[#This Row],[Age]]="66 and above",5)} -> 1 | E23: Okara | F23: easypaisa | G23: jazzcash | H23: 7 | I23: jazzcash | J23: Mostly use jazzcash | K23: Yes | L23: More preferable | M23: 10 | N23: jazzcash | O23: Maybe | P23: i have not seen this ad | Q23: Jazzcash | R23: 8
A24: DAC | B24: Male | C24: 18 - 29 | D24: {=_xlfn.IFS(SINGLE_RESPONSES[[#This Row],[Age]]="18 - 29",1, SINGLE_RESPONSES[[#This Row],[Age]]="30 - 41",2,SINGLE_RESPONSES[[#This Row],[Age]]="42 -53",3, SINGLE_RESPONSES[[#This Row],[Age]]="54 - 65",4, SINGLE_RESPONSES[[#This Row],[Age]]="66 and above",5)} -> 1 | E24: Lahore | F24: jazzcash | G24: jazzcash | H24: 7 | I24: nayapay | K24: Yes | L24: Bcz of its user friendly | M24: 10 | N24: nayapay | O24: Yes | P24: easypaisa | Q24: the convenience of online money transfer for festive gifts | R24: 7
A25: Momin Ali | B25: Male | C25: 18 - 29 | D25: {=_xlfn.IFS(SINGLE_RESPONSES[[#This Row],[Age]]="18 - 29",1, SINGLE_RESPONSES[[#This Row],[Age]]="30 - 41",2,SINGLE_RESPONSES[[#This Row],[Age]]="42 -53",3, SINGLE_RESPONSES[[#This Row],[Age]]="54 - 65",4, SINGLE_RESPONSES[[#This Row],[Age]]="66 and above",5)} -> 1 | E25: Gujrat | F25: easypaisa | G25: easypaisa | H25: 5 | I25: easypaisa | J25: Na | K25: Yes | L25: Availability | M25: 9 | N25: sadapay | P25: jazzcash | Q25: Dont remember much but i believe related to family n internet | R25: 9
A26: Iqra | B26: Female | C26: 18 - 29 | D26: {=_xlfn.IFS(SINGLE_RESPONSES[[#This Row],[Age]]="18 - 29",1, SINGLE_RESPONSES[[#This Row],[Age]]="30 - 41",2,SINGLE_RESPONSES[[#This Row],[Age]]="42 -53",3, SINGLE_RESPONSES[[#This Row],[Age]]="54 - 65",4, SINGLE_RESPONSES[[#This Row],[Age]]="66 and above",5)} -> 1 | E26: Lahore | F26: jazzcash | G26: jazzcash | H26: 7 | I26: jazzcash | J26: No change | K26: Yes | L26: It good | M26: 10 | N26: easypaisa | O26: No | P26: i have not seen this ad | Q26: No messs7 | R26: 1
A27: Amna | B27: Female | C27: 18 - 29 | D27: {=_xlfn.IFS(SINGLE_RESPONSES[[#This Row],[Age]]="18 - 29",1, SINGLE_RESPONSES[[#This Row],[Age]]="30 - 41",2,SINGLE_RESPONSES[[#This Row],[Age]]="42 -53",3, SINGLE_RESPONSES[[#This Row],[Age]]="54 - 65",4, SINGLE_RESPONSES[[#This Row],[Age]]="66 and above",5)} -> 1 | E27: Lahore | F27: jazzcash | G27: jazzcash | H27: 6 | I27: nayapay | J27: Using it for the first time. | K27: Yes | L27: Easy. | M27: 10 | N27: easypaisa | O27: Yes | P27: jazzcash | Q27: Faster money transfer | R27: 6
A28: Laiba | B28: Female | C28: 18 - 29 | D28: {=_xlfn.IFS(SINGLE_RESPONSES[[#This Row],[Age]]="18 - 29",1, SINGLE_RESPONSES[[#This Row],[Age]]="30 - 41",2,SINGLE_RESPONSES[[#This Row],[Age]]="42 -53",3, SINGLE_RESPONSES[[#This Row],[Age]]="54 - 65",4, SINGLE_RESPONSES[[#This Row],[Age]]="66 and above",5)} -> 1 | E28: Lahore | F28: jazzcash | G28: easypaisa | H28: 6 | I28: jazzcash | J28: Idk | K28: Yes | L28: Again idk, just using it. | M28: 9 | N28: jazzcash | O28: No | P28: i have not seen this ad | Q28: This should not be a required question. | R28: 1
A29: Haider shah | B29: Male | C29: 18 - 29 | D29: {=_xlfn.IFS(SINGLE_RESPONSES[[#This Row],[Age]]="18 - 29",1, SINGLE_RESPONSES[[#This Row],[Age]]="30 - 41",2,SINGLE_RESPONSES[[#This Row],[Age]]="42 -53",3, SINGLE_RESPONSES[[#This Row],[Age]]="54 - 65",4, SINGLE_RESPONSES[[#This Row],[Age]]="66 and above",5)} -> 1 | E29: Lahore | F29: easypaisa | G29: easypaisa | H29: 7 | I29: easypaisa | J29: Easypaisa is more essential | K29: Yes | L29: Its safe | M29: 4 | N29: nayapay | O29: No | P29: easypaisa | Q29: For forcing people to trust online platform | R29: 3
A30: Meerab Arshad | B30: Female | C30: 18 - 29 | D30: {=_xlfn.IFS(SINGLE_RESPONSES[[#This Row],[Age]]="18 - 29",1, SINGLE_RESPONSES[[#This Row],[Age]]="30 - 41",2,SINGLE_RESPONSES[[#This Row],[Age]]="42 -53",3, SINGLE_RESPONSES[[#This Row],[Age]]="54 - 65",4, SINGLE_RESPONSES[[#This Row],[Age]]="66 and above",5)} -> 1 | E30: Raiwind | F30: jazzcash | G30: jazzcash | H30: 2 | I30: jazzcash | J30: Jazz cash | K30: Yes | L30: Jazz cash | M30: 1 | N30: jazzcash | O30: Yes | P30: jazzcash | Q30: It's very helpful | R30: 1
A31: Muhammad Ziad Amir | B31: Male | C31: 18 - 29 | D31: {=_xlfn.IFS(SINGLE_RESPONSES[[#This Row],[Age]]="18 - 29",1, SINGLE_RESPONSES[[#This Row],[Age]]="30 - 41",2,SINGLE_RESPONSES[[#This Row],[Age]]="42 -53",3, SINGLE_RESPONSES[[#This Row],[Age]]="54 - 65",4, SINGLE_RESPONSES[[#This Row],[Age]]="66 and above",5)} -> 1 | E31: Lahore | F31: jazzcash | G31: sadapay | H31: 5 | I31: jazzcash | J31: App errors | K31: Yes | L31: Reliability | M31: 8 | N31: jazzcash | O31: Maybe | P31: easypaisa | Q31: Convinient for eidi transaction to your relatives | R31: 7
A32: Amina | B32: Female | C32: 30 - 41 | D32: {=_xlfn.IFS(SINGLE_RESPONSES[[#This Row],[Age]]="18 - 29",1, SINGLE_RESPONSES[[#This Row],[Age]]="30 - 41",2,SINGLE_RESPONSES[[#This Row],[Age]]="42 -53",3, SINGLE_RESPONSES[[#This Row],[Age]]="54 - 65",4, SINGLE_RESPONSES[[#This Row],[Age]]="66 and above",5)} -> 2 | E32: Lahore | F32: jazzcash | G32: jazzcash | H32: 7 | I32: jazzcash | J32: Today requirement in this digital world | K32: Yes | L32: One of the easy and fine way to send money around everywhere | M32: 9 | N32: none | O32: No | P32: i have not seen this ad | Q32: Not seen this ad | R32: 5
A33: Kanza | B33: Female | C33: 18 - 29 | D33: {=_xlfn.IFS(SINGLE_RESPONSES[[#This Row],[Age]]="18 - 29",1, SINGLE_RESPONSES[[#This Row],[Age]]="30 - 41",2,SINGLE_RESPONSES[[#This Row],[Age]]="42 -53",3, SINGLE_RESPONSES[[#This Row],[Age]]="54 - 65",4, SINGLE_RESPONSES[[#This Row],[Age]]="66 and above",5)} -> 1 | E33: Lahore | F33: sadapay | G33: sadapay | H33: 7 | I33: jazzcash | J33: I trust Sadapay better maybe cuz its not run locally | K33: Yes | L33: Convenience.. registering/ opening account in Sadapay was easy | M33: 8 | N33: none | O33: No | P33: i have not seen this ad | Q33: Accessibility, inclusivity | R33: 7
A34: Rana Ali Hassan | B34: Male | C34: 18 - 29 | D34: {=_xlfn.IFS(SINGLE_RESPONSES[[#This Row],[Age]]="18 - 29",1, SINGLE_RESPONSES[[#This Row],[Age]]="30 - 41",2,SINGLE_RESPONSES[[#This Row],[Age]]="42 -53",3, SINGLE_RESPONSES[[#This Row],[Age]]="54 - 65",4, SINGLE_RESPONSES[[#This Row],[Age]]="66 and above",5)} -> 1 | E34: Lahore | F34: easypaisa | G34: sadapay | H34: 3 | I34: sadapay | J34: Sometimes payment stuck and also some error are happened | K34: Yes | L34: It's used is simple, easy and safe | M34: 1 | N34: easypaisa | O34: No | P34: i have not seen this ad | Q34: To y Used digital app for payments | R34: 4
A35: amber | B35: Female | C35: 42 -53 | D35: {=_xlfn.IFS(SINGLE_RESPONSES[[#This Row],[Age]]="18 - 29",1, SINGLE_RESPONSES[[#This Row],[Age]]="30 - 41",2,SINGLE_RESPONSES[[#This Row],[Age]]="42 -53",3, SINGLE_RESPONSES[[#This Row],[Age]]="54 - 65",4, SINGLE_RESPONSES[[#This Row],[Age]]="66 and above",5)} -> 3 | E35: Lahore | F35: jazzcash | G35: jazzcash | H35: 2 | I35: easypaisa | J35: jazzcash is easy to use and am used to it now | K35: Yes | L35: for emergency if i need money to transfer anytime or anyone wants to return back my money | M35: 10 | N35: easypaisa | O35: Yes | P35: easypaisa | Q35: as everyone is using that app so transferred to their specific app through sadapay | R35: 10
A36: Naseer Ahmad | B36: Male | C36: 18 - 29 | D36: {=_xlfn.IFS(SINGLE_RESPONSES[[#This Row],[Age]]="18 - 29",1, SINGLE_RESPONSES[[#This Row],[Age]]="30 - 41",2,SINGLE_RESPONSES[[#This Row],[Age]]="42 -53",3, SINGLE_RESPONSES[[#This Row],[Age]]="54 - 65",4, SINGLE_RESPONSES[[#This Row],[Age]]="66 and above",5)} -> 1 | E36: Jhang | F36: easypaisa | G36: easypaisa | H36: 6 | I36: jazzcash | J36: For service issues | K36: Yes | L36: For good service | M36: 7 | N36: jazzcash | O36: Maybe | P36: easypaisa | Q36: It means this app is trustable and having fast service | R36: 7
A37: Mahnoor | B37: Female | C37: 18 - 29 | D37: {=_xlfn.IFS(SINGLE_RESPONSES[[#This Row],[Age]]="18 - 29",1, SINGLE_RESPONSES[[#This Row],[Age]]="30 - 41",2,SINGLE_RESPONSES[[#This Row],[Age]]="42 -53",3, SINGLE_RESPONSES[[#This Row],[Age]]="54 - 65",4, SINGLE_RESPONSES[[#This Row],[Age]]="66 and above",5)} -> 1 | E37: Lahore | F37: jazzcash | G37: jazzcash | H37: 4 | I37: jazzcash | J37: Is it good for myself and working fastly | K37: Yes | L37: Fast service | M37: 5 | N37: nayapay | O37: Maybe | P37: i have not seen this ad | Q37: To provide great service and advertising | R37: 3
... A151: Ghani Khan | B151: Male | C151: 18 - 29 | D151: {=_xlfn.IFS(SINGLE_RESPONSES[[#This Row],[Age]]="18 - 29",1, SINGLE_RESPONSES[[#This Row],[Age]]="30 - 41",2,SINGLE_RESPONSES[[#This Row],[Age]]="42 -53",3, SINGLE_RESPONSES[[#This Row],[Age]]="54 - 65",4, SINGLE_RESPONSES[[#This Row],[Age]]="66 and above",5)} -> 1 | E151: Faisalabad | F151: jazzcash | G151: jazzcash | H151: 7 | I151: jazzcash | J151: None | K151: Yes | L151: User friendly | M151: 7 | N151: easypaisa | O151: Maybe | P151: jazzcash | Q151: Easy access | R151: 5
B154: Gender analysis | G154: TOMA
C155: count | E155: Percentage | I155: count | J155: Percentage
B156: {=_xlfn.UNIQUE(SINGLE_RESPONSES[Gender])} -> Male | C156: =COUNTIF(SINGLE_RESPONSES[Gender],B156) -> 106 | E156: =C156/150 -> 0.70666667 | H156: easypaisa | I156: =COUNTIF(SINGLE_RESPONSES[TOM],H156) -> 46 | J156: =I156/150 -> 0.30666667
B157: Female | C157: =COUNTIF(SINGLE_RESPONSES[Gender],B157) -> 43 | E157: =C157/150 -> 0.28666667 | H157: sadapay | I157: =COUNTIF(SINGLE_RESPONSES[TOM],H157) -> 8 | J157: =I157/150 -> 0.053333333
B158: Prefer not to say | C158: =COUNTIF(SINGLE_RESPONSES[Gender],B158) -> 1 | E158: =C158/150 -> 0.0066666667 | H158: jazzcash | I158: =COUNTIF(SINGLE_RESPONSES[TOM],H158) -> 83 | J158: =I158/150 -> 0.55333333
H159: nayapay | I159: =COUNTIF(SINGLE_RESPONSES[TOM],H159) -> 10 | J159: =I159/150 -> 0.066666667
B176: Age group analysis
C177: count
A178: 18-29 | B178: {=_xlfn._xlws.SORT(_xlfn.UNIQUE(SINGLE_RESPONSES[coding]))} -> 1 | C178: =COUNTIF(SINGLE_RESPONSES[coding],B178) -> 127 | D178: =C178/150 -> 0.84666667
A179: 30-41 | B179: 2 | C179: =COUNTIF(SINGLE_RESPONSES[coding],B179) -> 15 | D179: =C179/150 -> 0.1
A180: 42-54 | B180: 3 | C180: =COUNTIF(SINGLE_RESPONSES[coding],B180) -> 5 | D180: =C180/150 -> 0.033333333
...

Sheet Main_Table
